<mujoco model="xhand_right">
  <compiler angle="radian" meshdir="meshes/" />

  <default>
    <!-- disable all contacts and use explicit collision pairs -->
    <geom density="800" condim="1" contype="0" conaffinity="0" />
    <!-- with this setting, the response time is around 1s -->
    <position kp="300" dampratio="1.0" inheritrange="1" />
    <joint damping="0.0" armature="1.0" frictionloss="0.0" />
    <site size="0.005" type="sphere" rgba="1 0 0 1" group="3" />
  </default>

  <asset>
    <texture type="skybox" builtin="gradient" rgb1="1.0 1.0 1.0" rgb2="1.0 1.0 1.0" width="512"
      height="3072" />
    <texture type="2d" name="right_groundplane" builtin="checker" mark="edge" rgb1="0.2 0.3 0.4"
      rgb2="0.1 0.2 0.3"
      markrgb="0.8 0.8 0.8" width="300" height="300" />
    <material name="right_groundplane" texture="right_groundplane" texuniform="true"
      texrepeat="5 5"
      reflectance="0.2" />
    <mesh name="right_hand_link" content_type="model/stl" file="right_hand_link.STL" />
    <mesh name="right_hand_thumb_bend_link" content_type="model/stl"
      file="right_hand_thumb_bend_link.STL" />
    <mesh name="right_hand_thumb_rota_link1" content_type="model/stl"
      file="right_hand_thumb_rota_link1.STL" />
    <mesh name="right_hand_thumb_rota_link2" content_type="model/stl"
      file="right_hand_thumb_rota_link2.STL" />
    <mesh name="right_hand_index_bend_link" content_type="model/stl"
      file="right_hand_index_bend_link.STL" />
    <mesh name="right_hand_index_rota_link1" content_type="model/stl"
      file="right_hand_index_rota_link1.STL" />
    <mesh name="right_hand_index_rota_link2" content_type="model/stl"
      file="right_hand_index_rota_link2.STL" />
    <mesh name="right_hand_mid_link1" content_type="model/stl" file="right_hand_mid_link1.STL" />
    <mesh name="right_hand_mid_link2" content_type="model/stl" file="right_hand_mid_link2.STL" />
    <mesh name="right_hand_ring_link1" content_type="model/stl" file="right_hand_ring_link1.STL" />
    <mesh name="right_hand_ring_link2" content_type="model/stl" file="right_hand_ring_link2.STL" />
    <mesh name="right_hand_pinky_link1" content_type="model/stl" file="right_hand_pinky_link1.STL" />
    <mesh name="right_hand_pinky_link2" content_type="model/stl" file="right_hand_pinky_link2.STL" />
  </asset>

  <worldbody>
    <body name="R_forearm_ty_link">
      <camera name="right_track" pos="-0.868 -0.348 -0.175"
        xyaxes="-0.037 0.999 -0.000 -0.011 -0.000 1.000" />
      <inertial pos="0 0 0" mass="0.1" diaginertia="0.01 0.01 0.01" />
      <joint name="R_forearm_tx_link_joint" pos="0 0 0" axis="1 0 0" type="slide" range="-5 5" />
      <body name="R_forearm_tz_link">
        <inertial pos="0 0 0" mass="0.1" diaginertia="0.01 0.01 0.01" />
        <joint name="R_forearm_ty_link_joint" pos="0 0 0" axis="0 1 0" type="slide" range="-5 5" />
        <body name="R_forearm_roll_link">
          <inertial pos="0 0 0" mass="0.1" diaginertia="0.01 0.01 0.01" />
          <joint name="R_forearm_tz_link_joint" pos="0 0 0" axis="0 0 1" type="slide" range="-5 5" />
          <body name="R_forearm_pitch_link">
            <inertial pos="0 0 0" mass="0.1" diaginertia="0.01 0.01 0.01" />
            <joint name="R_forearm_roll_link_joint" pos="0 0 0" axis="0 0 1" range="-6.2 6.2" />
            <body name="R_forearm_yaw_link">
              <inertial pos="0 0 0" mass="0.1" diaginertia="0.01 0.01 0.01" />
              <joint name="R_forearm_pitch_link_joint" pos="0 0 0" axis="1 0 0" range="-6.2 6.2" />
              <body name="right_hand_link">
                <inertial pos="-0.0071397 0.00342244 -0.0584807"
                  quat="0.688453 0.098553 0.0886255 0.713068" mass="0.530025"
                  diaginertia="0.00067782 0.000491189 0.000335821" />
                <joint name="R_forearm_yaw_link_joint" pos="0 0 0" axis="0 -1 0" range="-6.2 6.2" />
                <geom name="right_hand_link_visual" type="mesh" contype="0" conaffinity="0"
                  group="1" density="0" rgba="0.792157 0.819608 0.933333 1" mesh="right_hand_link" />
                <geom name="collision_hand_right_palm_0" type="box" size="0.04 0.024 0.04"
                  pos="0 0 -0.06"
                  rgba="0 1 0 1" group="3" />
                <site name="right_palm" pos="0 0 0" type="box" size="0.01 0.02 0.03" quat="0 1 1 0" />
                <body name="right_hand_thumb_bend_link" pos="0.0228 0.0095 -0.0305">
                  <inertial pos="0.0145291 -0.000901303 -0.000127926"
                    quat="0.0288921 0.68936 0.0166971 0.72365" mass="0.00985529"
                    diaginertia="1.30647e-06 1.29142e-06 5.40953e-07" />
                  <joint name="right_hand_thumb_bend_joint" pos="0 0 0" axis="0 0 1" range="0 1.83" />
                  <geom name="right_thumb_bend_visual" type="mesh" contype="0" conaffinity="0"
                    group="1" density="0" rgba="0.890196 0.890196 0.913725 1"
                    mesh="right_hand_thumb_bend_link" />
                  <geom name="collision_hand_right_thumb_2" type="capsule" size="0.015"
                    fromto="0 0 0 0.02 0 0"
                    rgba="0 1 0 1" group="3" />
                  <body name="right_hand_thumb_rota_link1" pos="0.028599 0.0083177 0.00178"
                    quat="0.99124 0.130499 0.00265603 0.0201745">
                    <inertial pos="0.0279237 -0.000127603 -0.000272577"
                      quat="-0.0989965 0.703671 0.0850598 0.698435" mass="0.153265"
                      diaginertia="5.62327e-05 4.89801e-05 2.23924e-05" />
                    <joint name="right_hand_thumb_rota_joint1" pos="0 0 0" axis="0 1 0"
                      range="-1.05 1.57" />
                    <geom name="right_thumb_rota1_visual" type="mesh" contype="0" conaffinity="0"
                      group="1" density="0" rgba="1 1 1 1" mesh="right_hand_thumb_rota_link1" />
                    <geom name="collision_hand_right_thumb_1" type="capsule" size="0.02"
                      fromto="0 0 0 0.055 0 0" rgba="0 1 0 1"
                      group="3" />
                    <body name="right_hand_thumb_rota_link2" pos="0.0553 0 0">
                      <inertial pos="0.0224697 -0.000691342 0.00302232"
                        quat="-0.0604029 0.715612 0.0198067 0.695599" mass="0.0374004"
                        diaginertia="9.5465e-06 8.27017e-06 3.92137e-06" />
                      <joint name="right_hand_thumb_rota_joint2" pos="0 0 0" axis="0 1 0"
                        range="-0.175 1.83" />
                      <geom name="right_thumb_rota2_visual" type="mesh" contype="0" conaffinity="0"
                        group="1" density="0" rgba="0.792157 0.819608 0.933333 1"
                        mesh="right_hand_thumb_rota_link2" />
                      <geom name="collision_hand_right_thumb_0" type="capsule" size="0.015"
                        fromto="0 0 0 0.04 0 0"
                        rgba="0 1 0 1"
                        group="3" />

                      <geom size="0.001" pos="0.0504025 0 0" contype="0" conaffinity="0" group="1"
                        density="0" rgba="0.698039 0.698039 0.698039 1" />
                      <site name="right_thumb_tip" pos="0.04 0 -0.012" />
                      <site name="track_hand_right_thumb_tip" pos="0.04 0 -0.012" />
                      <site name="trace_hand_right_thumb_tip" pos="0.04 0 -0.012" />
                    </body>
                  </body>
                </body>
                <body name="right_hand_index_bend_link" pos="0.0265 0.0065 -0.0899">
                  <inertial pos="8.08449e-05 0.000675884 0.00420851"
                    quat="0.999802 -0.0189928 -0.00582288 0.000998418" mass="0.0677836"
                    diaginertia="2.16592e-05 2.09943e-05 3.36803e-06" />
                  <joint name="right_hand_index_bend_joint" pos="0 0 0" axis="0 1 0"
                    range="-0.175 0.175" />
                  <geom name="right_index_bend_visual" type="mesh" contype="0" conaffinity="0"
                    group="1" density="0" rgba="0.439216 0.439216 0.439216 1"
                    mesh="right_hand_index_bend_link" />
                  <body name="right_hand_index_rota_link1" pos="0 0 -0.0178">
                    <inertial pos="-0.00013977 -0.000800517 -0.0356039"
                      quat="0.999865 0.00809183 -0.0131314 0.00566198" mass="0.0630216"
                      diaginertia="2.05301e-05 1.92461e-05 4.135e-06" />
                    <joint name="right_hand_index_joint1" pos="0 0 0" axis="1 0 0" range="0 1.92"
                    />
                    <geom name="right_index_rota1_visual" type="mesh" contype="0" conaffinity="0"
                      group="1" density="0" rgba="1 1 1 1" mesh="right_hand_index_rota_link1" />
                    <geom name="collision_hand_right_index_1" type="capsule" size="0.012"
                      fromto="0 0 0 0 0 -0.055" rgba="0 1 0 1" group="3" />
                    <body name="right_hand_index_rota_link2" pos="0 0 -0.0558">
                      <inertial pos="-0.000338569 1.93676e-05 -0.0231329"
                        quat="0.935384 0.00588977 -0.0260883 0.35262" mass="0.0179923"
                        diaginertia="3.02409e-06 3.01968e-06 9.82703e-07" />
                      <joint name="right_hand_index_joint2" pos="0 0 0" axis="1 0 0" range="0 1.92"
                      />
                      <geom name="right_index_rota2_visual" type="mesh" contype="0" conaffinity="0"
                        group="1" density="0" rgba="0.866667 0.866667 0.890196 1"
                        mesh="right_hand_index_rota_link2" />
                      <geom name="collision_hand_right_index_0" type="capsule" size="0.01"
                        fromto="0 0 0 0 0 -0.03" rgba="0 1 0 1" group="3" />
                      <geom size="0.001" pos="0 0 -0.0425" contype="0" conaffinity="0" group="1"
                        density="0" rgba="0.698039 0.698039 0.698039 1" />
                      <site name="right_index_tip" pos="0 0.004 -0.027" />
                      <site name="track_hand_right_index_tip" pos="0 0.004 -0.027" />
                      <site name="trace_hand_right_index_tip" pos="0 0.004 -0.027" />
                    </body>
                  </body>
                </body>
                <body name="right_hand_mid_link1" pos="0.004 0.0065 -0.1082">
                  <inertial pos="-0.000139769 -0.000800517 -0.0356039"
                    quat="0.999865 0.00809181 -0.0131314 0.00566199" mass="0.0630216"
                    diaginertia="2.05301e-05 1.92461e-05 4.135e-06" />
                  <joint name="right_hand_mid_joint1" pos="0 0 0" axis="1 0 0" range="0 1.92"
                  />
                  <geom name="right_middle_link1_visual" type="mesh" contype="0" conaffinity="0"
                    group="1" density="0" rgba="1 1 1 1" mesh="right_hand_mid_link1" />
                  <geom name="collision_hand_right_middle_1" type="capsule" size="0.012"
                    fromto="0 0 0 0 0 -0.055" rgba="0 1 0 1" group="3" />
                  <body name="right_hand_mid_link2" pos="0 0 -0.0558">
                    <inertial pos="-0.000338569 1.93676e-05 -0.0231329"
                      quat="0.935384 0.00588977 -0.0260883 0.35262" mass="0.0179923"
                      diaginertia="3.02409e-06 3.01968e-06 9.82703e-07" />
                    <joint name="right_hand_mid_joint2" pos="0 0 0" axis="1 0 0" range="0 1.94"
                    />
                    <geom name="right_middle_link2_visual" type="mesh" contype="0" conaffinity="0"
                      group="1" density="0" rgba="0.866667 0.866667 0.890196 1"
                      mesh="right_hand_mid_link2" />
                    <geom name="collision_hand_right_middle_0" type="capsule" size="0.01"
                      fromto="0 0 0 0 0 -0.03" rgba="0 1 0 1" group="3" />
                    <geom size="0.001" pos="0 0 -0.042107" contype="0" conaffinity="0" group="1"
                      density="0" rgba="0.698039 0.698039 0.698039 1" />
                    <site name="right_middle_tip" pos="0 0.004 -0.027" />
                    <site name="track_hand_right_middle_tip" pos="0 0.004 -0.027" />
                    <site name="trace_hand_right_middle_tip" pos="0 0.004 -0.027" />
                  </body>
                </body>
                <body name="right_hand_ring_link1" pos="-0.016 0.0065 -0.1052">
                  <inertial pos="-0.00013977 -0.000800517 -0.0356039"
                    quat="0.999865 0.00809183 -0.0131314 0.00566196" mass="0.0630216"
                    diaginertia="2.05301e-05 1.92461e-05 4.135e-06" />
                  <joint name="right_hand_ring_joint1" pos="0 0 0" axis="1 0 0" range="0 1.92"
                  />
                  <geom name="right_ring_link1_visual" type="mesh" contype="0" conaffinity="0"
                    group="1" density="0" rgba="1 1 1 1" mesh="right_hand_ring_link1" />
                  <geom name="collision_hand_right_ring_1" type="capsule" size="0.012"
                    fromto="0 0 0 0 0 -0.055" rgba="0 1 0 1" group="3" />
                  <body name="right_hand_ring_link2" pos="0 0 -0.0558">
                    <inertial pos="-0.000338573 1.93622e-05 -0.0231328"
                      quat="0.935372 0.00588872 -0.0260882 0.352652" mass="0.0179923"
                      diaginertia="3.02409e-06 3.01968e-06 9.82702e-07" />
                    <joint name="right_hand_ring_joint2" pos="0 0 0" axis="1 0 0" range="0 1.92"
                    />
                    <geom name="right_ring_link2_visual" type="mesh" contype="0" conaffinity="0"
                      group="1" density="0" rgba="0.866667 0.866667 0.890196 1"
                      mesh="right_hand_ring_link2" />
                    <geom name="collision_hand_right_ring_0" type="capsule" size="0.01"
                      fromto="0 0 0 0 0 -0.03" rgba="0 1 0 1" group="3" />
                    <geom size="0.001" pos="0 0 -0.0425" contype="0" conaffinity="0" group="1"
                      density="0" rgba="0.698039 0.698039 0.698039 1" />
                    <site name="right_ring_tip" pos="0 0.004 -0.027" />
                    <site name="track_hand_right_ring_tip" pos="0 0.004 -0.027" />
                    <site name="trace_hand_right_ring_tip" pos="0 0.004 -0.027" />
                  </body>
                </body>
                <body name="right_hand_pinky_link1" pos="-0.036 0.0065 -0.1022">
                  <inertial pos="-0.000139769 -0.000800517 -0.0356039"
                    quat="0.999865 0.00809181 -0.0131314 0.00566204" mass="0.0630216"
                    diaginertia="2.05301e-05 1.92461e-05 4.135e-06" />
                  <joint name="right_hand_pinky_joint1" pos="0 0 0" axis="1 0 0" range="0 1.92"
                  />
                  <geom name="right_pinky_link1_visual" type="mesh" contype="0" conaffinity="0"
                    group="1" density="0" rgba="1 1 1 1" mesh="right_hand_pinky_link1" />
                  <geom name="collision_hand_right_pinky_1" type="capsule" size="0.012"
                    fromto="0 0 0 0 0 -0.055" rgba="0 1 0 1" group="3" />
                  <body name="right_hand_pinky_link2" pos="0 0 -0.0558">
                    <inertial pos="-0.000338569 1.93676e-05 -0.0231329"
                      quat="0.935384 0.00588976 -0.0260883 0.352621" mass="0.0179923"
                      diaginertia="3.02409e-06 3.01968e-06 9.82703e-07" />
                    <joint name="right_hand_pinky_joint2" pos="0 0 0" axis="1 0 0" range="0 1.92"
                    />
                    <geom name="right_pinky_link2_visual" type="mesh" contype="0" conaffinity="0"
                      group="1" density="0" rgba="0.866667 0.866667 0.890196 1"
                      mesh="right_hand_pinky_link2" />
                    <geom name="collision_hand_right_pinky_0" type="capsule" size="0.01"
                      fromto="0 0 0 0 0 -0.03" rgba="0 1 0 1" group="3" />
                    <geom size="0.001" pos="0 0 -0.0425" contype="0" conaffinity="0" group="1"
                      density="0" rgba="0.698039 0.698039 0.698039 1" />
                    <site name="right_pinky_tip" pos="0 0.004 -0.027" />
                    <site name="track_hand_right_pinky_tip" pos="0 0.004 -0.027" />
                    <site name="trace_hand_right_pinky_tip" pos="0 0.004 -0.027" />
                  </body>
                </body>
              </body>
            </body>
          </body>
        </body>
      </body>
    </body>
  </worldbody>

  <actuator>
    <!-- Global position and rotation joints -->
    <position name="R_forearm_tx_position" joint="R_forearm_tx_link_joint" kp="1000" />
    <position name="R_forearm_ty_position" joint="R_forearm_ty_link_joint" kp="1000" />
    <position name="R_forearm_tz_position" joint="R_forearm_tz_link_joint" kp="1000" />
    <position name="R_forearm_roll_position" joint="R_forearm_roll_link_joint" kp="1000" />
    <position name="R_forearm_pitch_position" joint="R_forearm_pitch_link_joint" kp="1000" />
    <position name="R_forearm_yaw_position" joint="R_forearm_yaw_link_joint" kp="1000" />

    <!-- Thumb joints -->
    <position name="right_thumb_bend_position" joint="right_hand_thumb_bend_joint" />
    <position name="right_thumb_rota1_position" joint="right_hand_thumb_rota_joint1" />
    <position name="right_thumb_rota2_position" joint="right_hand_thumb_rota_joint2" />

    <!-- Index joints -->
    <position name="right_index_bend_position" joint="right_hand_index_bend_joint" />
    <position name="right_index_joint1_position" joint="right_hand_index_joint1" />
    <position name="right_index_joint2_position" joint="right_hand_index_joint2" />

    <!-- Middle joints -->
    <position name="right_middle_joint1_position" joint="right_hand_mid_joint1" />
    <position name="right_middle_joint2_position" joint="right_hand_mid_joint2" />

    <!-- Ring joints -->
    <position name="right_ring_joint1_position" joint="right_hand_ring_joint1" />
    <position name="right_ring_joint2_position" joint="right_hand_ring_joint2" />

    <!-- Pinky joints -->
    <position name="right_pinky_joint1_position" joint="right_hand_pinky_joint1" />
    <position name="right_pinky_joint2_position" joint="right_hand_pinky_joint2" />
  </actuator>
</mujoco>
